Workbook

Sheet Raw Data
A1: Order ID | B1: Date | C1: Region | D1: Category | E1: Product | F1: Sales Rep | G1: Units | H1: Unit Price | I1: Revenue | J1: Cost | K1: Profit | L1: Month # | M1: Month
A2: ORD-1068 | B2: 45660 | C2: North | D2: Sports | E2: Dumbbell Set | F2: Liam Chen | G2: 34 | H2: 89 | I2: =G2*H2 -> 3026 | J2: =ROUND(I2*0.629,2) -> 1903.35 | K2: =I2-J2 -> 1122.65 | L2: =MONTH(B2) -> 1 | M2: =TEXT(B2,"mmm") -> Jan
A3: ORD-1003 | B3: 45661 | C3: South | D3: Sports | E3: Tennis Racket | F3: Priya Nair | G3: 10 | H3: 69 | I3: =G3*H3 -> 690 | J3: =ROUND(I3*0.587,2) -> 405.03 | K3: =I3-J3 -> 284.97 | L3: =MONTH(B3) -> 1 | M3: =TEXT(B3,"mmm") -> Jan
A4: ORD-1135 | B4: 45665 | C4: South | D4: Sports | E4: Dumbbell Set | F4: Amara Okafor | G4: 31 | H4: 89 | I4: =G4*H4 -> 2759 | J4: =ROUND(I4*0.683,2) -> 1884.4 | K4: =I4-J4 -> 874.6 | L4: =MONTH(B4) -> 1 | M4: =TEXT(B4,"mmm") -> Jan
A5: ORD-1224 | B5: 45667 | C5: East | D5: Apparel | E5: Winter Jacket | F5: Sofia Rossi | G5: 39 | H5: 129 | I5: =G5*H5 -> 5031 | J5: =ROUND(I5*0.64,2) -> 3219.84 | K5: =I5-J5 -> 1811.16 | L5: =MONTH(B5) -> 1 | M5: =TEXT(B5,"mmm") -> Jan
A6: ORD-1118 | B6: 45668 | C6: East | D6: Electronics | E6: 4K Monitor | F6: Diego Fernandez | G6: 34 | H6: 289 | I6: =G6*H6 -> 9826 | J6: =ROUND(I6*0.661,2) -> 6494.99 | K6: =I6-J6 -> 3331.01 | L6: =MONTH(B6) -> 1 | M6: =TEXT(B6,"mmm") -> Jan
A7: ORD-1086 | B7: 45671 | C7: East | D7: Sports | E7: Camping Tent | F7: Kwame Mensah | G7: 13 | H7: 159 | I7: =G7*H7 -> 2067 | J7: =ROUND(I7*0.563,2) -> 1163.72 | K7: =I7-J7 -> 903.28 | L7: =MONTH(B7) -> 1 | M7: =TEXT(B7,"mmm") -> Jan
A8: ORD-1220 | B8: 45671 | C8: West | D8: Electronics | E8: Bluetooth Speaker | F8: Sofia Rossi | G8: 24 | H8: 45 | I8: =G8*H8 -> 1080 | J8: =ROUND(I8*0.59,2) -> 637.2 | K8: =I8-J8 -> 442.8 | L8: =MONTH(B8) -> 1 | M8: =TEXT(B8,"mmm") -> Jan
A9: ORD-1251 | B9: 45671 | C9: East | D9: Home & Garden | E9: Garden Hose | F9: Sofia Rossi | G9: 9 | H9: 22 | I9: =G9*H9 -> 198 | J9: =ROUND(I9*0.654,2) -> 129.49 | K9: =I9-J9 -> 68.51 | L9: =MONTH(B9) -> 1 | M9: =TEXT(B9,"mmm") -> Jan
A10: ORD-1056 | B10: 45672 | C10: North | D10: Home & Garden | E10: Patio Chair | F10: Sofia Rossi | G10: 17 | H10: 74 | I10: =G10*H10 -> 1258 | J10: =ROUND(I10*0.557,2) -> 700.71 | K10: =I10-J10 -> 557.29 | L10: =MONTH(B10) -> 1 | M10: =TEXT(B10,"mmm") -> Jan
A11: ORD-1078 | B11: 45672 | C11: West | D11: Home & Garden | E11: Garden Hose | F11: Kwame Mensah | G11: 11 | H11: 22 | I11: =G11*H11 -> 242 | J11: =ROUND(I11*0.693,2) -> 167.71 | K11: =I11-J11 -> 74.29 | L11: =MONTH(B11) -> 1 | M11: =TEXT(B11,"mmm") -> Jan
A12: ORD-1139 | B12: 45672 | C12: North | D12: Home & Garden | E12: Cordless Vacuum | F12: Priya Nair | G12: 23 | H12: 199 | I12: =G12*H12 -> 4577 | J12: =ROUND(I12*0.614,2) -> 2810.28 | K12: =I12-J12 -> 1766.72 | L12: =MONTH(B12) -> 1 | M12: =TEXT(B12,"mmm") -> Jan
A13: ORD-1026 | B13: 45674 | C13: East | D13: Electronics | E13: 4K Monitor | F13: Priya Nair | G13: 32 | H13: 289 | I13: =G13*H13 -> 9248 | J13: =ROUND(I13*0.586,2) -> 5419.33 | K13: =I13-J13 -> 3828.67 | L13: =MONTH(B13) -> 1 | M13: =TEXT(B13,"mmm") -> Jan
A14: ORD-1053 | B14: 45677 | C14: West | D14: Apparel | E14: Winter Jacket | F14: Diego Fernandez | G14: 23 | H14: 129 | I14: =G14*H14 -> 2967 | J14: =ROUND(I14*0.602,2) -> 1786.13 | K14: =I14-J14 -> 1180.87 | L14: =MONTH(B14) -> 1 | M14: =TEXT(B14,"mmm") -> Jan
A15: ORD-1039 | B15: 45678 | C15: North | D15: Sports | E15: Tennis Racket | F15: Priya Nair | G15: 14 | H15: 69 | I15: =G15*H15 -> 966 | J15: =ROUND(I15*0.664,2) -> 641.42 | K15: =I15-J15 -> 324.58 | L15: =MONTH(B15) -> 1 | M15: =TEXT(B15,"mmm") -> Jan
A16: ORD-1234 | B16: 45679 | C16: East | D16: Home & Garden | E16: Garden Hose | F16: Sofia Rossi | G16: 31 | H16: 22 | I16: =G16*H16 -> 682 | J16: =ROUND(I16*0.593,2) -> 404.43 | K16: =I16-J16 -> 277.57 | L16: =MONTH(B16) -> 1 | M16: =TEXT(B16,"mmm") -> Jan
A17: ORD-1240 | B17: 45679 | C17: East | D17: Sports | E17: Tennis Racket | F17: Kwame Mensah | G17: 4 | H17: 69 | I17: =G17*H17 -> 276 | J17: =ROUND(I17*0.563,2) -> 155.39 | K17: =I17-J17 -> 120.61 | L17: =MONTH(B17) -> 1 | M17: =TEXT(B17,"mmm") -> Jan
A18: ORD-1007 | B18: 45681 | C18: South | D18: Home & Garden | E18: Cordless Vacuum | F18: Liam Chen | G18: 7 | H18: 199 | I18: =G18*H18 -> 1393 | J18: =ROUND(I18*0.615,2) -> 856.7 | K18: =I18-J18 -> 536.3 | L18: =MONTH(B18) -> 1 | M18: =TEXT(B18,"mmm") -> Jan
A19: ORD-1185 | B19: 45683 | C19: North | D19: Home & Garden | E19: Garden Hose | F19: Kwame Mensah | G19: 28 | H19: 22 | I19: =G19*H19 -> 616 | J19: =ROUND(I19*0.633,2) -> 389.93 | K19: =I19-J19 -> 226.07 | L19: =MONTH(B19) -> 1 | M19: =TEXT(B19,"mmm") -> Jan
A20: ORD-1178 | B20: 45684 | C20: East | D20: Home & Garden | E20: LED Lamp | F20: Amara Okafor | G20: 37 | H20: 29 | I20: =G20*H20 -> 1073 | J20: =ROUND(I20*0.636,2) -> 682.43 | K20: =I20-J20 -> 390.57 | L20: =MONTH(B20) -> 1 | M20: =TEXT(B20,"mmm") -> Jan
A21: ORD-1029 | B21: 45685 | C21: North | D21: Electronics | E21: Bluetooth Speaker | F21: Kwame Mensah | G21: 22 | H21: 45 | I21: =G21*H21 -> 990 | J21: =ROUND(I21*0.686,2) -> 679.14 | K21: =I21-J21 -> 310.86 | L21: =MONTH(B21) -> 1 | M21: =TEXT(B21,"mmm") -> Jan
A22: ORD-1255 | B22: 45686 | C22: North | D22: Apparel | E22: Denim Jeans | F22: Liam Chen | G22: 11 | H22: 54 | I22: =G22*H22 -> 594 | J22: =ROUND(I22*0.605,2) -> 359.37 | K22: =I22-J22 -> 234.63 | L22: =MONTH(B22) -> 1 | M22: =TEXT(B22,"mmm") -> Jan
A23: ORD-1233 | B23: 45690 | C23: West | D23: Electronics | E23: Smart Watch | F23: Liam Chen | G23: 3 | H23: 179 | I23: =G23*H23 -> 537 | J23: =ROUND(I23*0.684,2) -> 367.31 | K23: =I23-J23 -> 169.69 | L23: =MONTH(B23) -> 2 | M23: =TEXT(B23,"mmm") -> Feb
A24: ORD-1055 | B24: 45693 | C24: East | D24: Home & Garden | E24: Garden Hose | F24: Kwame Mensah | G24: 35 | H24: 22 | I24: =G24*H24 -> 770 | J24: =ROUND(I24*0.606,2) -> 466.62 | K24: =I24-J24 -> 303.38 | L24: =MONTH(B24) -> 2 | M24: =TEXT(B24,"mmm") -> Feb
A25: ORD-1041 | B25: 45695 | C25: North | D25: Sports | E25: Yoga Mat | F25: Amara Okafor | G25: 35 | H25: 24 | I25: =G25*H25 -> 840 | J25: =ROUND(I25*0.586,2) -> 492.24 | K25: =I25-J25 -> 347.76 | L25: =MONTH(B25) -> 2 | M25: =TEXT(B25,"mmm") -> Feb
A26: ORD-1192 | B26: 45697 | C26: East | D26: Sports | E26: Camping Tent | F26: Kwame Mensah | G26: 27 | H26: 159 | I26: =G26*H26 -> 4293 | J26: =ROUND(I26*0.599,2) -> 2571.51 | K26: =I26-J26 -> 1721.49 | L26: =MONTH(B26) -> 2 | M26: =TEXT(B26,"mmm") -> Feb
A27: ORD-1021 | B27: 45698 | C27: North | D27: Sports | E27: Yoga Mat | F27: Sofia Rossi | G27: 9 | H27: 24 | I27: =G27*H27 -> 216 | J27: =ROUND(I27*0.572,2) -> 123.55 | K27: =I27-J27 -> 92.45 | L27: =MONTH(B27) -> 2 | M27: =TEXT(B27,"mmm") -> Feb
A28: ORD-1221 | B28: 45699 | C28: East | D28: Apparel | E28: Running Shoes | F28: Priya Nair | G28: 7 | H28: 89 | I28: =G28*H28 -> 623 | J28: =ROUND(I28*0.693,2) -> 431.74 | K28: =I28-J28 -> 191.26 | L28: =MONTH(B28) -> 2 | M28: =TEXT(B28,"mmm") -> Feb
A29: ORD-1209 | B29: 45701 | C29: East | D29: Sports | E29: Tennis Racket | F29: Liam Chen | G29: 34 | H29: 69 | I29: =G29*H29 -> 2346 | J29: =ROUND(I29*0.566,2) -> 1327.84 | K29: =I29-J29 -> 1018.16 | L29: =MONTH(B29) -> 2 | M29: =TEXT(B29,"mmm") -> Feb
A30: ORD-1252 | B30: 45702 | C30: North | D30: Home & Garden | E30: Garden Hose | F30: Kwame Mensah | G30: 31 | H30: 22 | I30: =G30*H30 -> 682 | J30: =ROUND(I30*0.639,2) -> 435.8 | K30: =I30-J30 -> 246.2 | L30: =MONTH(B30) -> 2 | M30: =TEXT(B30,"mmm") -> Feb
A31: ORD-1138 | B31: 45704 | C31: West | D31: Electronics | E31: Wireless Earbuds | F31: Diego Fernandez | G31: 11 | H31: 59 | I31: =G31*H31 -> 649 | J31: =ROUND(I31*0.668,2) -> 433.53 | K31: =I31-J31 -> 215.47 | L31: =MONTH(B31) -> 2 | M31: =TEXT(B31,"mmm") -> Feb
A32: ORD-1202 | B32: 45704 | C32: West | D32: Sports | E32: Yoga Mat | F32: Diego Fernandez | G32: 37 | H32: 24 | I32: =G32*H32 -> 888 | J32: =ROUND(I32*0.661,2) -> 586.97 | K32: =I32-J32 -> 301.03 | L32: =MONTH(B32) -> 2 | M32: =TEXT(B32,"mmm") -> Feb
A33: ORD-1176 | B33: 45707 | C33: East | D33: Apparel | E33: Running Shoes | F33: Sofia Rossi | G33: 36 | H33: 89 | I33: =G33*H33 -> 3204 | J33: =ROUND(I33*0.645,2) -> 2066.58 | K33: =I33-J33 -> 1137.42 | L33: =MONTH(B33) -> 2 | M33: =TEXT(B33,"mmm") -> Feb
A34: ORD-1109 | B34: 45708 | C34: South | D34: Apparel | E34: Denim Jeans | F34: Kwame Mensah | G34: 6 | H34: 54 | I34: =G34*H34 -> 324 | J34: =ROUND(I34*0.577,2) -> 186.95 | K34: =I34-J34 -> 137.05 | L34: =MONTH(B34) -> 2 | M34: =TEXT(B34,"mmm") -> Feb
A35: ORD-1001 | B35: 45710 | C35: North | D35: Sports | E35: Yoga Mat | F35: Amara Okafor | G35: 6 | H35: 24 | I35: =G35*H35 -> 144 | J35: =ROUND(I35*0.587,2) -> 84.53 | K35: =I35-J35 -> 59.47 | L35: =MONTH(B35) -> 2 | M35: =TEXT(B35,"mmm") -> Feb
A36: ORD-1030 | B36: 45713 | C36: South | D36: Apparel | E36: Winter Jacket | F36: Sofia Rossi | G36: 29 | H36: 129 | I36: =G36*H36 -> 3741 | J36: =ROUND(I36*0.574,2) -> 2147.33 | K36: =I36-J36 -> 1593.67 | L36: =MONTH(B36) -> 2 | M36: =TEXT(B36,"mmm") -> Feb
A37: ORD-1168 | B37: 45713 | C37: West | D37: Apparel | E37: Running Shoes | F37: Kwame Mensah | G37: 34 | H37: 89 | I37: =G37*H37 -> 3026 | J37: =ROUND(I37*0.601,2) -> 1818.63 | K37: =I37-J37 -> 1207.37 | L37: =MONTH(B37) -> 2 | M37: =TEXT(B37,"mmm") -> Feb
A38: ORD-1187 | B38: 45714 | C38: East | D38: Sports | E38: Tennis Racket | F38: Amara Okafor | G38: 15 | H38: 69 | I38: =G38*H38 -> 1035 | J38: =ROUND(I38*0.617,2) -> 638.6 | K38: =I38-J38 -> 396.4 | L38: =MONTH(B38) -> 2 | M38: =TEXT(B38,"mmm") -> Feb
A39: ORD-1225 | B39: 45714 | C39: East | D39: Apparel | E39: Denim Jeans | F39: Amara Okafor | G39: 4 | H39: 54 | I39: =G39*H39 -> 216 | J39: =ROUND(I39*0.591,2) -> 127.66 | K39: =I39-J39 -> 88.34 | L39: =MONTH(B39) -> 2 | M39: =TEXT(B39,"mmm") -> Feb
A40: ORD-1020 | B40: 45715 | C40: East | D40: Home & Garden | E40: Patio Chair | F40: Amara Okafor | G40: 16 | H40: 74 | I40: =G40*H40 -> 1184 | J40: =ROUND(I40*0.699,2) -> 827.62 | K40: =I40-J40 -> 356.38 | L40: =MONTH(B40) -> 2 | M40: =TEXT(B40,"mmm") -> Feb
...

Sheet Pivot Summary
A1: Pivot Summary
A2: Cross-tab summaries built with SUMIFS/SUMPRODUCT so every cell recalculates when Raw Data changes.
A4: Revenue by Region x Category
A5: Region | B5: Electronics | C5: Apparel | D5: Home & Garden | E5: Sports | F5: Total
A6: North | B6: =SUMIFS('Raw Data'!$I$2:$I$261,'Raw Data'!$C$2:$C$261,$A6,'Raw Data'!$D$2:$D$261,B$5) -> 36003 | C6: =SUMIFS('Raw Data'!$I$2:$I$261,'Raw Data'!$C$2:$C$261,$A6,'Raw Data'!$D$2:$D$261,C$5) -> 23798 | D6: =SUMIFS('Raw Data'!$I$2:$I$261,'Raw Data'!$C$2:$C$261,$A6,'Raw Data'!$D$2:$D$261,D$5) -> 31555 | E6: =SUMIFS('Raw Data'!$I$2:$I$261,'Raw Data'!$C$2:$C$261,$A6,'Raw Data'!$D$2:$D$261,E$5) -> 28465 | F6: =SUM(B6:E6) -> 119821
A7: South | B7: =SUMIFS('Raw Data'!$I$2:$I$261,'Raw Data'!$C$2:$C$261,$A7,'Raw Data'!$D$2:$D$261,B$5) -> 47938 | C7: =SUMIFS('Raw Data'!$I$2:$I$261,'Raw Data'!$C$2:$C$261,$A7,'Raw Data'!$D$2:$D$261,C$5) -> 23189 | D7: =SUMIFS('Raw Data'!$I$2:$I$261,'Raw Data'!$C$2:$C$261,$A7,'Raw Data'!$D$2:$D$261,D$5) -> 34335 | E7: =SUMIFS('Raw Data'!$I$2:$I$261,'Raw Data'!$C$2:$C$261,$A7,'Raw Data'!$D$2:$D$261,E$5) -> 28814 | F7: =SUM(B7:E7) -> 134276
A8: East | B8: =SUMIFS('Raw Data'!$I$2:$I$261,'Raw Data'!$C$2:$C$261,$A8,'Raw Data'!$D$2:$D$261,B$5) -> 63207 | C8: =SUMIFS('Raw Data'!$I$2:$I$261,'Raw Data'!$C$2:$C$261,$A8,'Raw Data'!$D$2:$D$261,C$5) -> 28927 | D8: =SUMIFS('Raw Data'!$I$2:$I$261,'Raw Data'!$C$2:$C$261,$A8,'Raw Data'!$D$2:$D$261,D$5) -> 28975 | E8: =SUMIFS('Raw Data'!$I$2:$I$261,'Raw Data'!$C$2:$C$261,$A8,'Raw Data'!$D$2:$D$261,E$5) -> 42042 | F8: =SUM(B8:E8) -> 163151
A9: West | B9: =SUMIFS('Raw Data'!$I$2:$I$261,'Raw Data'!$C$2:$C$261,$A9,'Raw Data'!$D$2:$D$261,B$5) -> 45098 | C9: =SUMIFS('Raw Data'!$I$2:$I$261,'Raw Data'!$C$2:$C$261,$A9,'Raw Data'!$D$2:$D$261,C$5) -> 19936 | D9: =SUMIFS('Raw Data'!$I$2:$I$261,'Raw Data'!$C$2:$C$261,$A9,'Raw Data'!$D$2:$D$261,D$5) -> 21467 | E9: =SUMIFS('Raw Data'!$I$2:$I$261,'Raw Data'!$C$2:$C$261,$A9,'Raw Data'!$D$2:$D$261,E$5) -> 23693 | F9: =SUM(B9:E9) -> 110194
A10: Total | B10: =SUM(B6:B9) -> 192246 | C10: =SUM(C6:C9) -> 95850 | D10: =SUM(D6:D9) -> 116332 | E10: =SUM(E6:E9) -> 123014 | F10: =SUM(F6:F9) -> 527442
A13: Monthly Revenue & Profit Trend
A14: Month | B14: Revenue | C14: Profit | D14: Units Sold
A15: Jan | B15: =SUMIFS('Raw Data'!$I$2:$I$261,'Raw Data'!$L$2:$L$261,1) -> 49559 | C15: =SUMIFS('Raw Data'!$K$2:$K$261,'Raw Data'!$L$2:$L$261,1) -> 18668.01 | D15: =SUMIFS('Raw Data'!$G$2:$G$261,'Raw Data'!$L$2:$L$261,1) -> 454
A16: Feb | B16: =SUMIFS('Raw Data'!$I$2:$I$261,'Raw Data'!$L$2:$L$261,2) -> 33591 | C16: =SUMIFS('Raw Data'!$K$2:$K$261,'Raw Data'!$L$2:$L$261,2) -> 12780.21 | D16: =SUMIFS('Raw Data'!$G$2:$G$261,'Raw Data'!$L$2:$L$261,2) -> 432
A17: Mar | B17: =SUMIFS('Raw Data'!$I$2:$I$261,'Raw Data'!$L$2:$L$261,3) -> 58659 | C17: =SUMIFS('Raw Data'!$K$2:$K$261,'Raw Data'!$L$2:$L$261,3) -> 20132.29 | D17: =SUMIFS('Raw Data'!$G$2:$G$261,'Raw Data'!$L$2:$L$261,3) -> 650
A18: Apr | B18: =SUMIFS('Raw Data'!$I$2:$I$261,'Raw Data'!$L$2:$L$261,4) -> 32615 | C18: =SUMIFS('Raw Data'!$K$2:$K$261,'Raw Data'!$L$2:$L$261,4) -> 10963.21 | D18: =SUMIFS('Raw Data'!$G$2:$G$261,'Raw Data'!$L$2:$L$261,4) -> 250
A19: May | B19: =SUMIFS('Raw Data'!$I$2:$I$261,'Raw Data'!$L$2:$L$261,5) -> 54903 | C19: =SUMIFS('Raw Data'!$K$2:$K$261,'Raw Data'!$L$2:$L$261,5) -> 20122.69 | D19: =SUMIFS('Raw Data'!$G$2:$G$261,'Raw Data'!$L$2:$L$261,5) -> 541
A20: Jun | B20: =SUMIFS('Raw Data'!$I$2:$I$261,'Raw Data'!$L$2:$L$261,6) -> 29678 | C20: =SUMIFS('Raw Data'!$K$2:$K$261,'Raw Data'!$L$2:$L$261,6) -> 10186.67 | D20: =SUMIFS('Raw Data'!$G$2:$G$261,'Raw Data'!$L$2:$L$261,6) -> 275
A21: Jul | B21: =SUMIFS('Raw Data'!$I$2:$I$261,'Raw Data'!$L$2:$L$261,7) -> 39748 | C21: =SUMIFS('Raw Data'!$K$2:$K$261,'Raw Data'!$L$2:$L$261,7) -> 14626.25 | D21: =SUMIFS('Raw Data'!$G$2:$G$261,'Raw Data'!$L$2:$L$261,7) -> 502
A22: Aug | B22: =SUMIFS('Raw Data'!$I$2:$I$261,'Raw Data'!$L$2:$L$261,8) -> 38716 | C22: =SUMIFS('Raw Data'!$K$2:$K$261,'Raw Data'!$L$2:$L$261,8) -> 14675.72 | D22: =SUMIFS('Raw Data'!$G$2:$G$261,'Raw Data'!$L$2:$L$261,8) -> 384
A23: Sep | B23: =SUMIFS('Raw Data'!$I$2:$I$261,'Raw Data'!$L$2:$L$261,9) -> 41082 | C23: =SUMIFS('Raw Data'!$K$2:$K$261,'Raw Data'!$L$2:$L$261,9) -> 14673.14 | D23: =SUMIFS('Raw Data'!$G$2:$G$261,'Raw Data'!$L$2:$L$261,9) -> 478
A24: Oct | B24: =SUMIFS('Raw Data'!$I$2:$I$261,'Raw Data'!$L$2:$L$261,10) -> 41637 | C24: =SUMIFS('Raw Data'!$K$2:$K$261,'Raw Data'!$L$2:$L$261,10) -> 14805.88 | D24: =SUMIFS('Raw Data'!$G$2:$G$261,'Raw Data'!$L$2:$L$261,10) -> 495
A25: Nov | B25: =SUMIFS('Raw Data'!$I$2:$I$261,'Raw Data'!$L$2:$L$261,11) -> 51888 | C25: =SUMIFS('Raw Data'!$K$2:$K$261,'Raw Data'!$L$2:$L$261,11) -> 18800.27 | D25: =SUMIFS('Raw Data'!$G$2:$G$261,'Raw Data'!$L$2:$L$261,11) -> 472
A26: Dec | B26: =SUMIFS('Raw Data'!$I$2:$I$261,'Raw Data'!$L$2:$L$261,12) -> 55366 | C26: =SUMIFS('Raw Data'!$K$2:$K$261,'Raw Data'!$L$2:$L$261,12) -> 20500 | D26: =SUMIFS('Raw Data'!$G$2:$G$261,'Raw Data'!$L$2:$L$261,12) -> 515
A29: Sales Rep Leaderboard
A30: Sales Rep | B30: Revenue | C30: Profit | D30: Orders | E30: Avg Order Value
A31: Amara Okafor | B31: =SUMIFS('Raw Data'!$I$2:$I$261,'Raw Data'!$F$2:$F$261,$A31) -> 75061 | C31: =SUMIFS('Raw Data'!$K$2:$K$261,'Raw Data'!$F$2:$F$261,$A31) -> 26462.22 | D31: =COUNTIFS('Raw Data'!$F$2:$F$261,$A31) -> 51 | E31: =IFERROR(B31/D31,0) -> 1471.7843
A32: Liam Chen | B32: =SUMIFS('Raw Data'!$I$2:$I$261,'Raw Data'!$F$2:$F$261,$A32) -> 81688 | C32: =SUMIFS('Raw Data'!$K$2:$K$261,'Raw Data'!$F$2:$F$261,$A32) -> 29953.17 | D32: =COUNTIFS('Raw Data'!$F$2:$F$261,$A32) -> 49 | E32: =IFERROR(B32/D32,0) -> 1667.102
A33: Kwame Mensah | B33: =SUMIFS('Raw Data'!$I$2:$I$261,'Raw Data'!$F$2:$F$261,$A33) -> 121371 | C33: =SUMIFS('Raw Data'!$K$2:$K$261,'Raw Data'!$F$2:$F$261,$A33) -> 43930.75 | D33: =COUNTIFS('Raw Data'!$F$2:$F$261,$A33) -> 48 | E33: =IFERROR(B33/D33,0) -> 2528.5625
A34: Priya Nair | B34: =SUMIFS('Raw Data'!$I$2:$I$261,'Raw Data'!$F$2:$F$261,$A34) -> 107330 | C34: =SUMIFS('Raw Data'!$K$2:$K$261,'Raw Data'!$F$2:$F$261,$A34) -> 38769.76 | D34: =COUNTIFS('Raw Data'!$F$2:$F$261,$A34) -> 38 | E34: =IFERROR(B34/D34,0) -> 2824.4737
A35: Sofia Rossi | B35: =SUMIFS('Raw Data'!$I$2:$I$261,'Raw Data'!$F$2:$F$261,$A35) -> 69374 | C35: =SUMIFS('Raw Data'!$K$2:$K$261,'Raw Data'!$F$2:$F$261,$A35) -> 25827.41 | D35: =COUNTIFS('Raw Data'!$F$2:$F$261,$A35) -> 38 | E35: =IFERROR(B35/D35,0) -> 1825.6316
A36: Diego Fernandez | B36: =SUMIFS('Raw Data'!$I$2:$I$261,'Raw Data'!$F$2:$F$261,$A36) -> 72618 | C36: =SUMIFS('Raw Data'!$K$2:$K$261,'Raw Data'!$F$2:$F$261,$A36) -> 25991.03 | D36: =COUNTIFS('Raw Data'!$F$2:$F$261,$A36) -> 36 | E36: =IFERROR(B36/D36,0) -> 2017.1667

Sheet Dashboard
A1: Sales Performance Dashboard
A2: FY2025 | Interactive filters below drive every KPI card via SUMPRODUCT array formulas | K2: FALSE | L2: ◀ Tick to send the report now
A4: Region: | B4: All | D4: Category: | E4: All
A6: Total Revenue | C6: Total Profit | E6: Units Sold | G6: Orders | I6: Profit Margin
A7: =SUMPRODUCT(('Raw Data'!$C$2:$C$261=IF($B$4="All",'Raw Data'!$C$2:$C$261,$B$4))*('Raw Data'!$D$2:$D$261=IF($E$4="All",'Raw Data'!$D$2:$D$261,$E$4))*'Raw Data'!$I$2:$I$261) -> 527442 | C7: =SUMPRODUCT(('Raw Data'!$C$2:$C$261=IF($B$4="All",'Raw Data'!$C$2:$C$261,$B$4))*('Raw Data'!$D$2:$D$261=IF($E$4="All",'Raw Data'!$D$2:$D$261,$E$4))*'Raw Data'!$K$2:$K$261) -> 190934.34 | E7: =SUMPRODUCT(('Raw Data'!$C$2:$C$261=IF($B$4="All",'Raw Data'!$C$2:$C$261,$B$4))*('Raw Data'!$D$2:$D$261=IF($E$4="All",'Raw Data'!$D$2:$D$261,$E$4))*'Raw Data'!$G$2:$G$261) -> 5448 | G7: =SUMPRODUCT(('Raw Data'!$C$2:$C$261=IF($B$4="All",'Raw Data'!$C$2:$C$261,$B$4))*('Raw Data'!$D$2:$D$261=IF($E$4="All",'Raw Data'!$D$2:$D$261,$E$4))) -> 260 | I7: =IFERROR(SUMPRODUCT(('Raw Data'!$C$2:$C$261=IF($B$4="All",'Raw Data'!$C$2:$C$261,$B$4))*('Raw Data'!$D$2:$D$261=IF($E$4="All",'Raw Data'!$D$2:$D$261,$E$4))*'Raw Data'!$K$2:$K$261)/SUMPRODUCT(('Raw Data'!$C$2:$C$261=IF($B$4="All",'Raw Data'!$C$2:$C$261,$B$4))*('Raw Data'!$D$2:$D$261=IF($E$4="All",'Raw Data'!$D$2:$D$261,$E$4))*'Raw Data'!$I$2:$I$261),0) -> 0.36200064
A10: Revenue by Region | F10: Category Share
A28: Monthly Revenue Trend | I28: Top Sales Reps
I29: Sales Rep | J29: Revenue
I30: ='Pivot Summary'!A31 -> Amara Okafor | J30: ='Pivot Summary'!B31 -> 75061
I31: ='Pivot Summary'!A32 -> Liam Chen | J31: ='Pivot Summary'!B32 -> 81688
I32: ='Pivot Summary'!A33 -> Kwame Mensah | J32: ='Pivot Summary'!B33 -> 121371
I33: ='Pivot Summary'!A34 -> Priya Nair | J33: ='Pivot Summary'!B34 -> 107330
I34: ='Pivot Summary'!A35 -> Sofia Rossi | J34: ='Pivot Summary'!B35 -> 69374
I35: ='Pivot Summary'!A36 -> Diego Fernandez | J35: ='Pivot Summary'!B36 -> 72618

Sheet Recipients
A1: Email | B1: Name (optional)
A2: muthusimat2@gmail.com | B2: Stakeholder One

Sheet Read Me
A3: How this workbook is built
A4: • Raw Data: a structured Excel Table (SalesData) with 260 orders. Revenue, Cost, Profit, and Month are all formulas. Edit or extend the raw rows and everything downstream recalculates.
A5: • Pivot Summary: cross-tab and trend tables built with SUMIFS/COUNTIFS. The same result as an Excel/Google Sheets PivotTable, but formula-driven so it survives file conversion and recalculates automatically.
A6: • Dashboard: KPI cards and charts driven by two dropdown filters (Region, Category). The KPI formulas use SUMPRODUCT with an embedded IF which is an Excel native equivalent of an array formula, to let 'All' mean 'ignore this filter'.
A7: Turning this into a native PivotTable
A8: 1. Select any cell inside the SalesData table on the Raw Data tab.
A9: 2. Excel: Insert → PivotTable → New Worksheet. Google Sheets: Insert → Pivot table.
A10: 3. Drag Region / Category to Rows or Columns, and Revenue / Profit to Values.
A11: 4. Right-click → Refresh any time you add rows to Raw Data.
A13: Google Sheets equivalents (QUERY / ARRAYFORMULA)
A14: These functions are not supported by the recalculation engine used to build this file, so the workbook uses SUMIFS/SUMPRODUCT instead. If you upload this file to Google Sheets, you can replace the Pivot Summary and Dashboard formulas with the QUERY/ARRAYFORMULA versions below:
A15: Region x Category revenue (single formula, replaces the whole cross-tab):
... A29: • Add a new dropdown value to the Data Validation list on B4/E4 to filter by a new Region or Category once you add it to Raw Data.
